Workbook

Sheet Raw Data
A1: 立讯精密 (002475.SZ) — Raw Financial Data (CNY millions)
B3: FY2021 | C3: FY2022 | D3: FY2023 | E3: FY2024 | F3: FY2025
A5: Income Statement
A6: Revenue | B6: 1539 | C6: 2140 | D6: 2319 | E6: 2687 | F6: 3323.44
A7: Cost of Revenue | B7: 1342 | C7: 1872 | D7: 2050 | E7: 2380 | F7: 2928.32
A8: Gross Profit | B8: 197 | C8: 268 | D8: 269 | E8: 307 | F8: 395.12
A9: Gross Margin % | B9: 0.128 | C9: 0.125 | D9: 0.116 | E9: 0.114 | F9: 0.1191
A10: R&D Expense | B10: 66.42 | C10: 85.6 | D10: 100.19 | E10: 85.6 | F10: 114.28
A11: SG&A Expense | B11: 68 | C11: 95 | D11: 110 | E11: 125 | F11: 155
A12: D&A | B12: 45 | C12: 60 | D12: 75 | E12: 90 | F12: 110
A13: Operating Income | B13: 85 | C13: 115 | D13: 120 | E13: 135 | F13: 165
A14: Operating Margin % | B14: 0.055 | C14: 0.054 | D14: 0.052 | E14: 0.05 | F14: 0.05
A15: Interest Income | B15: 2 | C15: 3 | D15: 4 | E15: 5 | F15: 4
A16: Interest Expense | B16: 8 | C16: 12 | D16: 15 | E16: 18 | F16: 22
A17: EBT | B17: 79 | C17: 106 | D17: 109 | E17: 122 | F17: 147
... A25: SBC | B25: 5 | C25: 6 | D25: 7 | E25: 8 | F25: 10
A27: Balance Sheet
A28: Cash & Equivalents | B28: 120 | C28: 150 | D28: 180 | E28: 200 | F28: 220
A29: Accounts Receivable | B29: 280 | C29: 350 | D29: 400 | E29: 450 | F29: 520
A30: Inventory | B30: 180 | C30: 250 | D30: 300 | E30: 350 | F30: 420
A31: Total Current Assets | B31: 620 | C31: 800 | D31: 950 | E31: 1080 | F31: 1280
A32: Net PP&E | B32: 450 | C32: 600 | D32: 750 | E32: 900 | F32: 1100
A33: Goodwill + Intangibles | B33: 80 | C33: 120 | D33: 150 | E33: 200 | F33: 280
A34: Total Assets | B34: 1200 | C34: 1600 | D34: 1950 | E34: 2300 | F34: 2800
A35: Accounts Payable | B35: 320 | C35: 420 | D35: 500 | E35: 580 | F35: 700
A36: Current Debt | B36: 80 | C36: 100 | D36: 120 | E36: 150 | F36: 180
A37: Total Current Liabilities | B37: 480 | C37: 620 | D37: 750 | E37: 880 | F37: 1050
A38: Long-Term Debt | B38: 200 | C38: 280 | D38: 350 | E38: 420 | F38: 500
A39: Total Liabilities | B39: 720 | C39: 950 | D39: 1150 | E39: 1350 | F39: 1620
... A42: Total L&E | B42: 1200 | C42: 1600 | D42: 1950 | E42: 2300 | F42: 2800
A44: Cash Flow Statement
A45: CFO | B45: 120 | C45: 150 | D45: 180 | E45: 271 | F45: 173.25
A46: CapEx | B46: 80 | C46: 110 | D46: 140 | E46: 170 | F46: 200
A47: FCF | B47: 40 | C47: 40 | D47: 40 | E47: 101 | F47: -26.75
A48: Net Debt Issuance | B48: 30 | C48: 40 | D48: 50 | E48: 60 | F48: 80
A49: Dividends | B49: 15 | C49: 20 | D49: 25 | E49: 30 | F49: 35
A51: Key Ratios
A52: ROE | B52: 0.14 | C52: 0.139 | D52: 0.116 | E52: 0.109 | F52: 0.211
A53: ROA | B53: 0.056 | C53: 0.056 | D53: 0.048 | E53: 0.045 | F53: 0.045
A54: D/E Ratio | B54: 0.58 | C54: 0.58 | D54: 0.59 | E54: 0.59 | F54: 0.59
...

Sheet Operating Drivers
A1: 立讯精密 (002475.SZ) — Operating Drivers & Assumptions (CNY millions)
B3: FY2021 | C3: FY2022 | D3: FY2023 | E3: FY2024 | F3: FY2025 | G3: FY2026E | H3: FY2027E | I3: FY2028E | J3: FY2029E | K3: FY2030E | L3: Source | M3: Rationale
A5: Revenue Growth Drivers
A6: Revenue YoY Growth % | B6: 0.391 | C6: 0.084 | D6: 0.159 | E6: 0.236 | F6: 0.236 | G6: 0.23 | H6: 0.14 | I6: 0.13 | J6: 0.1 | K6: 0.08 | L6: Consensus + our adj | M6: 2026E consensus +23%, 2027-2030E converge to industry long-term growth
A7: Gross Margin % | B7: 0.128 | C7: 0.125 | D7: 0.116 | E7: 0.114 | F7: 0.119 | G7: 0.122 | H7: 0.125 | I7: 0.128 | J7: 0.13 | K7: 0.132 | L7: Historical avg + mix | M7: High GM auto/comm segments growing faster; scale effects +0.5pct/yr
A8: R&D / Revenue % | B8: 0.043 | C8: 0.04 | D8: 0.043 | E8: 0.032 | F8: 0.034 | G8: 0.035 | H8: 0.036 | I8: 0.036 | J8: 0.036 | K8: 0.036 | L8: Mgmt guidance | M8: Sustained R&D investment for auto/AI infrastructure; stabilize at 3.6%
A9: SG&A / Revenue % | B9: 0.044 | C9: 0.044 | D9: 0.047 | E9: 0.047 | F9: 0.047 | G9: 0.046 | H9: 0.045 | I9: 0.044 | J9: 0.043 | K9: 0.042 | L9: Historical trend | M9: Operating leverage + efficiency gains; -5bps/yr
A10: D&A / Revenue % | B10: 0.029 | C10: 0.028 | D10: 0.032 | E10: 0.034 | F10: 0.033 | G10: 0.034 | H10: 0.034 | I10: 0.033 | J10: 0.032 | K10: 0.031 | L10: Historical trend | M10: CapEx intensity ~6%; depreciation ~3.3%
A11: Tax Rate (Normalized) % | B11: 0.15 | C11: 0.15 | D11: 0.15 | E11: 0.15 | F11: 0.15 | G11: 0.15 | H11: 0.15 | I11: 0.15 | J11: 0.15 | K11: 0.15 | L11: Statutory rate | M11: China enterprise income tax 15% (high-tech status) + minor adjustments
A12: Interest Income Rate % | B12: 0.017 | C12: 0.02 | D12: 0.022 | E12: 0.025 | F12: 0.018 | G12: 0.02 | H12: 0.02 | I12: 0.02 | J12: 0.02 | K12: 0.02 | L12: Market rate | M12: Cash yield on bank deposits ~2%
A13: Interest Expense Rate % | B13: 0.04 | C13: 0.043 | D13: 0.043 | E13: 0.043 | F13: 0.044 | G13: 0.044 | H13: 0.044 | I13: 0.044 | J13: 0.044 | K13: 0.044 | L13: Debt avg rate | M13: Weighted avg debt cost ~4.4%
A15: Balance Sheet Assumptions
A16: AR Days (DSO) | B16: 66 | C16: 60 | D16: 63 | E16: 61 | F16: 57 | G16: 58 | H16: 58 | I16: 57 | J16: 57 | K16: 57 | L16: Historical avg | M16: Stable around 57-58 days
A17: Inventory Days (DIO) | B17: 43 | C17: 43 | D17: 47 | E17: 54 | F17: 52 | G17: 52 | H17: 51 | I17: 51 | J17: 50 | K17: 50 | L17: Historical avg | M17: Slight improvement from inventory mgmt
A18: AP Days (DPO) | B18: 76 | C18: 82 | D18: 89 | E18: 89 | F18: 87 | G18: 88 | H18: 88 | I18: 88 | J18: 88 | K18: 88 | L18: Historical avg | M18: Stable around 88 days
A19: CapEx / Revenue % | B19: 0.052 | C19: 0.051 | D19: 0.06 | E19: 0.063 | F19: 0.06 | G19: 0.06 | H19: 0.058 | I19: 0.055 | J19: 0.053 | K19: 0.05 | L19: Mgmt guidance | M19: Auto/AI infra expansion; slight decline as scale grows
A20: SBC / Revenue % | B20: 0.003 | C20: 0.003 | D20: 0.003 | E20: 0.003 | F20: 0.003 | G20: 0.003 | H20: 0.003 | I20: 0.003 | J20: 0.003 | K20: 0.003 | L20: Historical | M20: SBC stable at 0.3%
A21: Dividend Payout Ratio % | B21: 0.223 | C21: 0.222 | D21: 0.27 | E21: 0.289 | F21: 0.28 | G21: 0.28 | H21: 0.28 | I21: 0.28 | J21: 0.28 | K21: 0.28 | L21: Policy | M21: Stable ~28% payout
A23: Other Assumptions
A24: Diluted Shares (M) | B24: 7180 | C24: 7180 | D24: 7180 | E24: 7180 | F24: 7249 | G24: 7250 | H24: 7250 | I24: 7250 | J24: 7250 | K24: 7250 | L24: Company data | M24: Minor share dilution; H-share listing may increase

Sheet Revenue Model
A1: 立讯精密 (002475.SZ) — Revenue Model by Segment (CNY millions)
B3: FY2021 | C3: FY2022 | D3: FY2023 | E3: FY2024 | F3: FY2025 | G3: FY2026E | H3: FY2027E | I3: FY2028E | J3: FY2029E | K3: FY2030E
A5: Consumer Electronics
A6: Revenue | B6: 2073 | C6: 2140 | D6: 2073 | E6: 2330 | F6: 2642.66 | G6: 2906.93 | H6: 3197.62 | I6: 3453.43 | J6: 3626.1 | K6: 3761.15
A7: YoY Growth % | B7: 0.032 | C7: 0 | D7: -0.031 | E7: 0.124 | F7: 0.134 | G7: 0.1 | H7: 0.1 | I7: 0.08 | J7: 0.05 | K7: 0.037
A8: % of Total
A9: Auto Electronics
A10: Revenue | B10: 41 | C10: 61 | D10: 61 | E10: 137.5 | F10: 392.55 | G10: 628.08 | H10: 879.31 | I10: 1143.1 | J10: 1428.88 | K10: 1714.65
A11: YoY Growth % | B11: 0.488 | C11: 0 | D11: 0 | E11: 1.254 | F11: 1.853 | G11: 0.6 | H11: 0.4 | I11: 0.3 | J11: 0.25 | K11: 0.2
A12: % of Total
A13: Comm & Data Center
A14: Revenue | B14: 33 | C14: 183.5 | D14: 183.5 | E14: 183.5 | F14: 245.68 | G14: 331.67 | H14: 431.17 | I14: 539.67 | J14: 646.49 | K14: 745.46
A15: YoY Growth % | B15: 4.561 | C15: 0 | D15: 0 | E15: 0 | F15: 0.338 | G15: 0.35 | H15: 0.3 | I15: 0.25 | J15: 0.2 | K15: 0.153
A16: % of Total
A17: Other
A18: Revenue | B18: 119 | C18: 1.5 | D18: 1.5 | E18: 30 | F18: 42.55 | G18: 48 | H18: 52 | I18: 55 | J18: 57 | K18: 58
A19: YoY Growth % | B19: -0.987 | C19: 0 | D19: 0 | E19: 19 | F19: 0.418 | G19: 0.128 | H19: 0.083 | I19: 0.058 | J19: 0.036 | K19: 0.018
A20: % of Total
A21: Total Revenue | B21: 1539 | C21: 2140 | D21: 2319 | E21: 2687 | F21: 3323.44 | G21: 3914.68 | H21: 4559.1 | I21: 5191.2 | J21: 5758.47 | K21: 6279.26
A22: Total YoY Growth %

Sheet Income Statement
A1: 立讯精密 (002475.SZ) — Income Statement (CNY millions)
B3: FY2021 | C3: FY2022 | D3: FY2023 | E3: FY2024 | F3: FY2025 | G3: FY2026E | H3: FY2027E | I3: FY2028E | J3: FY2029E | K3: FY2030E
A5: Total Revenue | B5: ='Revenue Model'!B18 | C5: ='Revenue Model'!C18 | D5: ='Revenue Model'!D18 | E5: ='Revenue Model'!E18 | F5: ='Revenue Model'!F18 | G5: ='Revenue Model'!G18 | H5: ='Revenue Model'!H18 | I5: ='Revenue Model'!I18 | ... K5: ='Revenue Model'!K18
A6: YoY Growth %
A7: Cost of Revenue
A8: Gross Profit
A9: Gross Margin %
A10: R&D Expense
A11: SG&A Expense
A12: D&A
A13: Operating Income (EBIT)
A14: Operating Margin %
A15: Interest Income
A16: Interest Expense
A17: EBT
... A24: SBC

Sheet Balance Sheet
A1: 立讯精密 (002475.SZ) — Balance Sheet (CNY millions)
B3: FY2021 | C3: FY2022 | D3: FY2023 | E3: FY2024 | F3: FY2025 | G3: FY2026E | H3: FY2027E | I3: FY2028E | J3: FY2029E | K3: FY2030E
A5: Cash & Equivalents
A6: Accounts Receivable
A7: Inventory
A8: Prepaid & Other Current
A9: Total Current Assets
A10: Net PP&E
A11: Goodwill
A12: Intangible Assets
A13: Other Non-Current Assets
A14: Total Non-Current Assets
A15: Total Assets
A16: Accounts Payable
... A29: ⚠️ BALANCE CHECK

Sheet Cash Flow
A1: 立讯精密 (002475.SZ) — Cash Flow Statement (CNY millions)
B3: FY2021 | C3: FY2022 | D3: FY2023 | E3: FY2024 | F3: FY2025 | G3: FY2026E | H3: FY2027E | I3: FY2028E | J3: FY2029E | K3: FY2030E
A5: Net Income
A6: + D&A
A7: + SBC
A8: Change in Receivables
A9: Change in Inventory
A10: Change in Payables
A11: Other WC Changes
A12: CFO
A13: Capital Expenditure
A14: Acquisitions
A15: CFI
A16: Net Debt Issuance
... A24: FCF Margin %

Sheet DCF
A1: 立讯精密 (002475.SZ) — DCF Valuation (CNY millions except per share)
A3: WACC Calculation
A4: Risk-Free Rate | B4: 0.025 | C4: China 10Y bond yield
A5: Beta | B5: 1.2 | C5: A-share electronics avg
A6: Equity Risk Premium | B6: 0.065 | C6: A-share premium
A7: Size Premium | B7: 0.005 | C7: Large cap
A8: Cost of Equity (Ke) | B8: =B5+B6*B7+B8 | C8: CAPM
A9: Cost of Debt (pre-tax) | B9: 0.044 | C9: Weighted avg
A10: Tax Rate | B10: 0.15 | C10: Effective
A11: Cost of Debt (after-tax) | B11: =B10*(1-B11)
A12: Market Cap (Equity) | B12: 4865000 | C12: Current
A13: Total Debt | B13: 680 | C13: BS total
A14: Equity Weight (E/V) | B14: =B13/(B13+B14)
A15: Debt Weight (D/V) | B15: =B14/(B13+B14)
A16: WACC | B16: =B9*B15+B12*B16
A18: FCF Projection + Discounting
A19: Revenue | G19: FY2026E | H19: FY2027E | I19: FY2028E | J19: FY2029E | K19: FY2030E
A20: EBIT
A21: NOPAT (EBIT*(1-t))
A22: + D&A
A23: - CapEx
A24: - Change in NWC
A25: Unlevered FCF
A26: Discount Factor
A27: PV of UFCF
A29: Terminal Value
A30: Terminal Growth Rate
A31: Terminal UFCF
A32: Terminal Value (Gordon)
... A46: Upside/(Downside) %

Sheet Comps
A1: 立讯精密 (002475.SZ) — Comparable Company Analysis (CNY millions)
A3: Company | B3: Ticker | C3: Market Cap | D3: Revenue(TTM) | E3: EBITDA(TTM) | F3: Net Income | G3: EV/Rev | H3: EV/EBITDA | I3: P/E(TTM) | J3: P/E(NTM) | K3: P/B | L3: P/S | M3: PEG
A4: 工业富联 | B4: 601138.SH | C4: 14200 | D4: 9029 | E4: 700 | F4: 353 | G4: 1.6 | H4: 20.3 | I4: 35 | J4: 25 | K4: 8.1 | L4: 1.6 | M4: 0.7
A5: 歌尔股份 | B5: 002241.SZ | C5: 850 | D5: 900 | E5: 80 | F5: 30 | G5: 0.9 | H5: 10.6 | I5: 28 | J5: 22 | K5: 3.2 | L5: 0.9 | M5: 1
A6: 蓝思科技 | B6: 300433.SZ | C6: 600 | D6: 550 | E6: 100 | F6: 45 | G6: 1.1 | H6: 6 | I6: 13 | J6: 11 | K6: 2.5 | L6: 1.1 | M6: 0.8
A7: 鹏鼎控股 | B7: 002938.SZ | C7: 450 | D7: 350 | E7: 60 | F7: 35 | G7: 1.3 | H7: 7.5 | I7: 13 | J7: 11 | K7: 2.8 | L7: 1.3 | M7: 0.9
A8: 中航光电 | B8: 002179.SZ | C8: 380 | D8: 180 | E8: 45 | F8: 25 | G8: 2.1 | H8: 8.4 | I8: 15 | J8: 13 | K8: 4 | L8: 2.1 | M8: 1.2
A9: 立讯精密 | B9: 002475.SZ | C9: 4865 | D9: 3323 | E9: 395 | F9: 166 | G9: 1.5 | H9: 12 | I9: 17.3 | J9: 15 | K9: 4.5 | L9: 1.5 | M9: 0.8
A11: Statistical Summary
A12: Maximum | H12: =MAX(H4:H8) | I12: =MAX(I4:I8) | J12: =MAX(J4:J8) | K12: =MAX(K4:K8) | L12: =MAX(L4:L8) | M12: =MAX(M4:M8)
A13: 75th Pctl | H13: =PERCENTILE.INC(H4:H8,0.75) | I13: =PERCENTILE.INC(I4:I8,0.75) | J13: =PERCENTILE.INC(J4:J8,0.75) | K13: =PERCENTILE.INC(K4:K8,0.75) | L13: =PERCENTILE.INC(L4:L8,0.75) | M13: =PERCENTILE.INC(M4:M8,0.75)
A14: Median | H14: =MEDIAN(H4:H8) | I14: =MEDIAN(I4:I8) | J14: =MEDIAN(J4:J8) | K14: =MEDIAN(K4:K8) | L14: =MEDIAN(L4:L8) | M14: =MEDIAN(M4:M8)
A15: Mean | H15: =AVERAGE(H4:H8) | I15: =AVERAGE(I4:I8) | J15: =AVERAGE(J4:J8) | K15: =AVERAGE(K4:K8) | L15: =AVERAGE(L4:L8) | M15: =AVERAGE(M4:M8)
A16: 25th Pctl | H16: =PERCENTILE.INC(H4:H8,0.25) | I16: =PERCENTILE.INC(I4:I8,0.25) | J16: =PERCENTILE.INC(J4:J8,0.25) | K16: =PERCENTILE.INC(K4:K8,0.25) | L16: =PERCENTILE.INC(L4:L8,0.25) | M16: =PERCENTILE.INC(M4:M8,0.25)
A17: Minimum | H17: =MIN(H4:H8) | I17: =MIN(I4:I8) | J17: =MIN(J4:J8) | K17: =MIN(K4:K8) | L17: =MIN(L4:L8) | M17: =MIN(M4:M8)
A18: Target | H18: =H9 | I18: =I9 | J18: =J9 | K18: =K9 | L18: =L9 | M18: =M9
A19: Percentile | H19: =PERCENTRANK.INC(H4:H8,H9) | I19: =PERCENTRANK.INC(I4:I8,I9) | J19: =PERCENTRANK.INC(J4:J8,J9) | K19: =PERCENTRANK.INC(K4:K8,K9) | L19: =PERCENTRANK.INC(L4:L8,L9) | M19: =PERCENTRANK.INC(M4:M8,M9)

Sheet Sensitivity
A1: 立讯精密 (002475.SZ) — DCF Sensitivity: WACC vs Terminal Growth Rate
A3: Equity Value/Share | B3: 0.015 | C3: 0.02 | D3: 0.025 | E3: 0.03 | F3: 0.035
A4: 0.08 | B4: ="DCF"!B33 | C4: ="DCF"!B33 | D4: ="DCF"!B33 | E4: ="DCF"!B33 | F4: ="DCF"!B33
A5: 0.085 | B5: ="DCF"!B33 | C5: ="DCF"!B33 | D5: ="DCF"!B33 | E5: ="DCF"!B33 | F5: ="DCF"!B33
A6: 0.09 | B6: ="DCF"!B33 | C6: ="DCF"!B33 | D6: ="DCF"!B33 | E6: ="DCF"!B33 | F6: ="DCF"!B33
A7: 0.095 | B7: ="DCF"!B33 | C7: ="DCF"!B33 | D7: ="DCF"!B33 | E7: ="DCF"!B33 | F7: ="DCF"!B33
A8: 0.1 | B8: ="DCF"!B33 | C8: ="DCF"!B33 | D8: ="DCF"!B33 | E8: ="DCF"!B33 | F8: ="DCF"!B33

Sheet Scenarios
A1: 立讯精密 (002475.SZ) — Scenario Analysis
B3: Bull Case | C3: Base Case | D3: Bear Case
A5: Probability | B5: 0.2 | C5: 0.55 | D5: 0.25
A7: Key Assumptions
A8: Revenue CAGR (5Y) | B8: 0.28 | C8: 0.23 | D8: 0.15
A9: Terminal Gross Margin | B9: 0.13 | C9: 0.125 | D9: 0.11
A10: Terminal Op Margin | B10: 0.06 | C10: 0.055 | D10: 0.045
A11: WACC | B11: 0.09 | C11: 0.095 | D11: 0.1
A12: Terminal Growth | B12: 0.03 | C12: 0.025 | D12: 0.02
A14: Outputs
A15: FY2028E Revenue | B15: 5758 | C15: 5191 | D15: 4317
A16: FY2028E EPS | B16: 3.85 | C16: 3.2 | D16: 2.15
A17: DCF Implied Price | B17: 85 | C17: 72 | D17: 55
A18: Target P/E | B18: 22 | C18: 19 | D18: 16
A19: Implied Price (PE) | B19: 84.7 | C19: 60.8 | D19: 34.4
A21: Probability-Weighted Price | B21: =B5*B19+C5*C19+D5*D19
A22: Current Price | B22: 67.12
A23: Upside/(Downside) % | B23: =B21/B22-1
